<robot name="onshape">
<link name="base">
<visual>
<origin xyz="0.00435679 -0.103872 0.03943" rpy="0 -0 0" />
<geometry>
<mesh filename="package://base.stl"/>
</geometry>
<material name="base_material">
<color rgba="0.615686 0.811765 0.929412 1.0"/>
</material>
</visual>
<collision>
<origin xyz="0.00435679 -0.103872 0.03943" rpy="0 -0 0" />
<geometry>
<mesh filename="package://base.stl"/>
</geometry>
<material name="base_material">
<color rgba="0.615686 0.811765 0.929412 1.0"/>
</material>
</collision>
<inertial>
<origin xyz="0 0 0" rpy="0 0 0"/>
<mass value="0" />
<inertia ixx="0" ixy="0"  ixz="0" iyy="0" iyz="0" izz="0" />
</inertial>
</link>

<link name="link_v2">
<visual>
<origin xyz="0 0 -0.5" rpy="1.5708 -0 0" />
<geometry>
<mesh filename="package://link_v2.stl"/>
</geometry>
<material name="link_v2_material">
<color rgba="0.615686 0.811765 0.929412 1.0"/>
</material>
</visual>
<collision>
<origin xyz="0 0 -0.5" rpy="1.5708 -0 0" />
<geometry>
<mesh filename="package://link_v2.stl"/>
</geometry>
<material name="link_v2_material">
<color rgba="0.615686 0.811765 0.929412 1.0"/>
</material>
</collision>
<inertial>
<origin xyz="0.00155634 3.39676e-19 -0.2725" rpy="0 0 0"/>
<mass value="0.680678" />
<inertia ixx="0.0176816" ixy="0"  ixz="-0.000283974" iyy="0.01768" iyz="0" izz="0.000843963" />
</inertial>
</link>

<link name="part_1">
<visual>
<origin xyz="1.38778e-17 -0.075 0" rpy="0 1.22465e-16 1.36846e-48" />
<geometry>
<mesh filename="package://part_1.stl"/>
</geometry>
<material name="part_1_material">
<color rgba="0.615686 0.811765 0.929412 1.0"/>
</material>
</visual>
<collision>
<origin xyz="1.38778e-17 -0.075 0" rpy="0 1.22465e-16 1.36846e-48" />
<geometry>
<mesh filename="package://part_1.stl"/>
</geometry>
<material name="part_1_material">
<color rgba="0.615686 0.811765 0.929412 1.0"/>
</material>
</collision>
<inertial>
<origin xyz="1.03136e-17 -0.028125 -0.0126452" rpy="0 0 0"/>
<mass value="4.05265" />
<inertia ixx="0.00634122" ixy="-1.17268e-19"  ixz="-7.93606e-20" iyy="0.0041645" iyz="0.000957567" izz="0.00698925" />
</inertial>
</link>

<link name="link_v2_2">
<visual>
<origin xyz="-8.67362e-19 0 -0.5" rpy="1.5708 -0 -1.84105e-49" />
<geometry>
<mesh filename="package://link_v2.stl"/>
</geometry>
<material name="link_v2_material">
<color rgba="0.615686 0.811765 0.929412 1.0"/>
</material>
</visual>
<collision>
<origin xyz="-8.67362e-19 0 -0.5" rpy="1.5708 -0 -1.84105e-49" />
<geometry>
<mesh filename="package://link_v2.stl"/>
</geometry>
<material name="link_v2_material">
<color rgba="0.615686 0.811765 0.929412 1.0"/>
</material>
</collision>
<inertial>
<origin xyz="0.00155634 3.39676e-19 -0.2725" rpy="0 0 0"/>
<mass value="0.680678" />
<inertia ixx="0.0176816" ixy="0"  ixz="-0.000283974" iyy="0.01768" iyz="0" izz="0.000843963" />
</inertial>
</link>

<link name="part_1_2">
<visual>
<origin xyz="1.38778e-17 -0.075 8.67362e-19" rpy="0 1.22465e-16 0" />
<geometry>
<mesh filename="package://part_1.stl"/>
</geometry>
<material name="part_1_material">
<color rgba="0.615686 0.811765 0.929412 1.0"/>
</material>
</visual>
<collision>
<origin xyz="1.38778e-17 -0.075 8.67362e-19" rpy="0 1.22465e-16 0" />
<geometry>
<mesh filename="package://part_1.stl"/>
</geometry>
<material name="part_1_material">
<color rgba="0.615686 0.811765 0.929412 1.0"/>
</material>
</collision>
<inertial>
<origin xyz="1.03136e-17 -0.028125 -0.0126452" rpy="0 0 0"/>
<mass value="4.05265" />
<inertia ixx="0.00634122" ixy="-1.17268e-19"  ixz="-7.93606e-20" iyy="0.0041645" iyz="0.000957567" izz="0.00698925" />
</inertial>
</link>

<link name="link_v1">
<visual>
<origin xyz="-6.93889e-18 0 -3.37849e-19" rpy="-1.5708 -0 -2.02515e-48" />
<geometry>
<mesh filename="package://link_v1.stl"/>
</geometry>
<material name="link_v1_material">
<color rgba="0.615686 0.811765 0.929412 1.0"/>
</material>
</visual>
<collision>
<origin xyz="-6.93889e-18 0 -3.37849e-19" rpy="-1.5708 -0 -2.02515e-48" />
<geometry>
<mesh filename="package://link_v1.stl"/>
</geometry>
<material name="link_v1_material">
<color rgba="0.615686 0.811765 0.929412 1.0"/>
</material>
</collision>
<inertial>
<origin xyz="-5.21333e-18 4.03616e-18 -0.25" rpy="0 0 0"/>
<mass value="0.628319" />
<inertia ixx="0.0134827" ixy="0"  ixz="-2.8895e-50" iyy="0.0134827" iyz="0" izz="0.000785398" />
</inertial>
</link>

<link name="tip_plate">
<visual>
<origin xyz="0 0 -3.37849e-19" rpy="-1.5708 -0 -2.02515e-48" />
<geometry>
<mesh filename="package://tip_plate.stl"/>
</geometry>
<material name="tip_plate_material">
<color rgba="0.615686 0.811765 0.929412 1.0"/>
</material>
</visual>
<collision>
<origin xyz="0 0 -3.37849e-19" rpy="-1.5708 -0 -2.02515e-48" />
<geometry>
<mesh filename="package://tip_plate.stl"/>
</geometry>
<material name="tip_plate_material">
<color rgba="0.615686 0.811765 0.929412 1.0"/>
</material>
</collision>
<inertial>
<origin xyz="1.72556e-18 4.03616e-18 -0.0125" rpy="0 0 0"/>
<mass value="0.0314159" />
<inertia ixx="2.12712e-05" ixy="0"  ixz="-1.22605e-52" iyy="2.12712e-05" iyz="0" izz="3.92699e-05" />
</inertial>
</link>

<joint name="joint_top" type="revolute">
<origin xyz="-4.59702e-17 0 -0.5" rpy="0 -0 -2.02515e-48" />
<parent link="link_v1" />
<child link="tip_plate" />
<axis xyz="0 0 1"/>
<limit effort="1" velocity="20" />
<joint_properties friction="0.0"/>
</joint>

<joint name="joint_5" type="revolute">
<origin xyz="1.38778e-17 -0.075 -2.60209e-18" rpy="-1.5708 -1.5708 0" />
<parent link="part_1_2" />
<child link="link_v1" />
<axis xyz="0 0 1"/>
<limit effort="1" velocity="20" />
<joint_properties friction="0.0"/>
</joint>

<joint name="joint_4" type="revolute">
<origin xyz="8.67362e-19 -2.08167e-17 -0.55" rpy="1.5708 8.43157e-43 1.5708" />
<parent link="link_v2_2" />
<child link="part_1_2" />
<axis xyz="0 0 1"/>
<limit effort="1" velocity="20" lower="-1.5708" upper="1.5708"/>
<joint_properties friction="0.0"/>
</joint>

<joint name="joint_3" type="revolute">
<origin xyz="2.08167e-17 -0.075 4.33681e-18" rpy="-1.5708 -1.5708 0" />
<parent link="part_1" />
<child link="link_v2_2" />
<axis xyz="0 0 1"/>
<limit effort="1" velocity="20" />
<joint_properties friction="0.0"/>
</joint>

<joint name="joint_2" type="revolute">
<origin xyz="2.60209e-18 -1.38778e-17 -0.55" rpy="1.5708 1.63003e-47 1.5708" />
<parent link="link_v2" />
<child link="part_1" />
<axis xyz="0 0 1"/>
<limit effort="1" velocity="20" lower="-1.5708" upper="1.5708"/>
<joint_properties friction="0.0"/>
</joint>

<joint name="joint_1" type="revolute">
<origin xyz="0.00435679 -0.103872 0.03943" rpy="1.5708 -0 0" />
<parent link="base" />
<child link="link_v2" />
<axis xyz="0 0 1"/>
<limit effort="1" velocity="20" />
<joint_properties friction="0.0"/>
</joint>


</robot>
